2019-04-12 22:34:26,761 ERROR: Exception on /index [GET] [in /home/pi/microblog/venv/lib/python3.6/site-packages/flask/app.py:1761]
Traceback (most recent call last):
  File "/home/pi/microblog/venv/lib/python3.6/site-packages/flask/app.py", line 2292, in wsgi_app
    response = self.full_dispatch_request()
  File "/home/pi/microblog/venv/lib/python3.6/site-packages/flask/app.py", line 1815, in full_dispatch_request
    rv = self.handle_user_exception(e)
  File "/home/pi/microblog/venv/lib/python3.6/site-packages/flask/app.py", line 1718, in handle_user_exception
    reraise(exc_type, exc_value, tb)
  File "/home/pi/microblog/venv/lib/python3.6/site-packages/flask/_compat.py", line 35, in reraise
    raise value
  File "/home/pi/microblog/venv/lib/python3.6/site-packages/flask/app.py", line 1813, in full_dispatch_request
    rv = self.dispatch_request()
  File "/home/pi/microblog/venv/lib/python3.6/site-packages/flask/app.py", line 1799, in dispatch_request
    return self.view_functions[rule.endpoint](**req.view_args)
  File "/home/pi/microblog/venv/lib/python3.6/site-packages/flask_login/utils.py", line 261, in decorated_view
    return func(*args, **kwargs)
  File "/home/pi/microblog/app/main/routes.py", line 35, in index
    prev_url=prev_url)
  File "/home/pi/microblog/venv/lib/python3.6/site-packages/flask/templating.py", line 135, in render_template
    context, ctx.app)
  File "/home/pi/microblog/venv/lib/python3.6/site-packages/flask/templating.py", line 117, in _render
    rv = template.render(context)
  File "/home/pi/microblog/venv/lib/python3.6/site-packages/jinja2/asyncsupport.py", line 76, in render
    return original_render(self, *args, **kwargs)
  File "/home/pi/microblog/venv/lib/python3.6/site-packages/jinja2/environment.py", line 1008, in render
    return self.environment.handle_exception(exc_info, True)
  File "/home/pi/microblog/venv/lib/python3.6/site-packages/jinja2/environment.py", line 780, in handle_exception
    reraise(exc_type, exc_value, tb)
  File "/home/pi/microblog/venv/lib/python3.6/site-packages/jinja2/_compat.py", line 37, in reraise
    raise value.with_traceback(tb)
  File "/home/pi/microblog/app/templates/index.html", line 2, in top-level template code
    {% import 'bootstrap/wtf.html' as wtf %}
  File "/home/pi/microblog/app/templates/base.html", line 1, in top-level template code
    {% extends 'bootstrap/base.html' %}
  File "/home/pi/microblog/venv/lib/python3.6/site-packages/flask_bootstrap/templates/bootstrap/base.html", line 1, in top-level template code
    {% block doc -%}
  File "/home/pi/microblog/venv/lib/python3.6/site-packages/flask_bootstrap/templates/bootstrap/base.html", line 4, in block "doc"
    {%- block html %}
  File "/home/pi/microblog/venv/lib/python3.6/site-packages/flask_bootstrap/templates/bootstrap/base.html", line 6, in block "html"
    {%- block head %}
  File "/home/pi/microblog/venv/lib/python3.6/site-packages/flask_bootstrap/templates/bootstrap/base.html", line 13, in block "head"
    {%- block styles %}
  File "/home/pi/microblog/app/templates/base.html", line 115, in block "styles"
    <link rel="stylesheet" href="{{url_for('static/css', filename='style.css')}}">
  File "/home/pi/microblog/venv/lib/python3.6/site-packages/flask/helpers.py", line 356, in url_for
    return appctx.app.handle_url_build_error(error, endpoint, values)
  File "/home/pi/microblog/venv/lib/python3.6/site-packages/flask/app.py", line 2061, in handle_url_build_error
    reraise(exc_type, exc_value, tb)
  File "/home/pi/microblog/venv/lib/python3.6/site-packages/flask/_compat.py", line 35, in reraise
    raise value
  File "/home/pi/microblog/venv/lib/python3.6/site-packages/flask/helpers.py", line 345, in url_for
    force_external=external)
  File "/home/pi/microblog/venv/lib/python3.6/site-packages/werkzeug/routing.py", line 1776, in build
    raise BuildError(endpoint, values, method, self)
werkzeug.routing.BuildError: Could not build url for endpoint 'static/css' with values ['filename']. Did you mean 'static' instead?
2019-04-12 22:38:25,498 ERROR: Exception on /index [GET] [in /home/pi/microblog/venv/lib/python3.6/site-packages/flask/app.py:1761]
Traceback (most recent call last):
  File "/home/pi/microblog/venv/lib/python3.6/site-packages/flask/app.py", line 2292, in wsgi_app
    response = self.full_dispatch_request()
  File "/home/pi/microblog/venv/lib/python3.6/site-packages/flask/app.py", line 1815, in full_dispatch_request
    rv = self.handle_user_exception(e)
  File "/home/pi/microblog/venv/lib/python3.6/site-packages/flask/app.py", line 1718, in handle_user_exception
    reraise(exc_type, exc_value, tb)
  File "/home/pi/microblog/venv/lib/python3.6/site-packages/flask/_compat.py", line 35, in reraise
    raise value
  File "/home/pi/microblog/venv/lib/python3.6/site-packages/flask/app.py", line 1813, in full_dispatch_request
    rv = self.dispatch_request()
  File "/home/pi/microblog/venv/lib/python3.6/site-packages/flask/app.py", line 1799, in dispatch_request
    return self.view_functions[rule.endpoint](**req.view_args)
  File "/home/pi/microblog/venv/lib/python3.6/site-packages/flask_login/utils.py", line 261, in decorated_view
    return func(*args, **kwargs)
  File "/home/pi/microblog/app/main/routes.py", line 35, in index
    prev_url=prev_url)
  File "/home/pi/microblog/venv/lib/python3.6/site-packages/flask/templating.py", line 135, in render_template
    context, ctx.app)
  File "/home/pi/microblog/venv/lib/python3.6/site-packages/flask/templating.py", line 117, in _render
    rv = template.render(context)
  File "/home/pi/microblog/venv/lib/python3.6/site-packages/jinja2/asyncsupport.py", line 76, in render
    return original_render(self, *args, **kwargs)
  File "/home/pi/microblog/venv/lib/python3.6/site-packages/jinja2/environment.py", line 1008, in render
    return self.environment.handle_exception(exc_info, True)
  File "/home/pi/microblog/venv/lib/python3.6/site-packages/jinja2/environment.py", line 780, in handle_exception
    reraise(exc_type, exc_value, tb)
  File "/home/pi/microblog/venv/lib/python3.6/site-packages/jinja2/_compat.py", line 37, in reraise
    raise value.with_traceback(tb)
  File "/home/pi/microblog/app/templates/index.html", line 2, in top-level template code
    {% import 'bootstrap/wtf.html' as wtf %}
  File "/home/pi/microblog/app/templates/base.html", line 1, in top-level template code
    {% extends 'bootstrap/base.html' %}
  File "/home/pi/microblog/venv/lib/python3.6/site-packages/flask_bootstrap/templates/bootstrap/base.html", line 1, in top-level template code
    {% block doc -%}
  File "/home/pi/microblog/venv/lib/python3.6/site-packages/flask_bootstrap/templates/bootstrap/base.html", line 4, in block "doc"
    {%- block html %}
  File "/home/pi/microblog/venv/lib/python3.6/site-packages/flask_bootstrap/templates/bootstrap/base.html", line 6, in block "html"
    {%- block head %}
  File "/home/pi/microblog/venv/lib/python3.6/site-packages/flask_bootstrap/templates/bootstrap/base.html", line 13, in block "head"
    {%- block styles %}
  File "/home/pi/microblog/app/templates/base.html", line 115, in block "styles"
    <link rel="stylesheet" href="{{url_for('static', filename='css/style.css')}}">
  File "/home/pi/microblog/venv/lib/python3.6/site-packages/flask/helpers.py", line 356, in url_for
    return appctx.app.handle_url_build_error(error, endpoint, values)
  File "/home/pi/microblog/venv/lib/python3.6/site-packages/flask/app.py", line 2061, in handle_url_build_error
    reraise(exc_type, exc_value, tb)
  File "/home/pi/microblog/venv/lib/python3.6/site-packages/flask/_compat.py", line 35, in reraise
    raise value
  File "/home/pi/microblog/venv/lib/python3.6/site-packages/flask/helpers.py", line 345, in url_for
    force_external=external)
  File "/home/pi/microblog/venv/lib/python3.6/site-packages/werkzeug/routing.py", line 1776, in build
    raise BuildError(endpoint, values, method, self)
werkzeug.routing.BuildError: Could not build url for endpoint 'static/css' with values ['filename']. Did you mean 'static' instead?
2019-04-12 22:38:45,340 INFO: Le blog startup [in /home/pi/microblog/app/__init__.py:70]
2019-04-19 09:58:49,854 INFO: Le blog startup [in /home/pi/microblog/app/__init__.py:70]
2019-04-19 10:01:22,575 INFO: Le blog startup [in /home/pi/microblog/app/__init__.py:70]
2019-04-19 13:00:36,809 INFO: Le blog startup [in /home/pi/microblog/app/__init__.py:73]
2019-04-19 13:00:48,045 ERROR: Exception on /explore [GET] [in /home/pi/microblog/venv/lib/python3.6/site-packages/flask/app.py:1761]
Traceback (most recent call last):
  File "/home/pi/microblog/venv/lib/python3.6/site-packages/flask/app.py", line 2292, in wsgi_app
    response = self.full_dispatch_request()
  File "/home/pi/microblog/venv/lib/python3.6/site-packages/flask/app.py", line 1815, in full_dispatch_request
    rv = self.handle_user_exception(e)
  File "/home/pi/microblog/venv/lib/python3.6/site-packages/flask/app.py", line 1718, in handle_user_exception
    reraise(exc_type, exc_value, tb)
  File "/home/pi/microblog/venv/lib/python3.6/site-packages/flask/_compat.py", line 35, in reraise
    raise value
  File "/home/pi/microblog/venv/lib/python3.6/site-packages/flask/app.py", line 1811, in full_dispatch_request
    rv = self.preprocess_request()
  File "/home/pi/microblog/venv/lib/python3.6/site-packages/flask/app.py", line 2087, in preprocess_request
    rv = func()
  File "/home/pi/microblog/app/main/routes.py", line 16, in before_request
    g.locale = str(get_locale())
NameError: name 'get_locale' is not defined
